2018-09-21 14:54:20,293 INFO: Microblog startup [in C:\Users\Prince\Desktop\microblog2\app\__init__.py:50]
2018-09-21 18:13:16,817 INFO: Microblog startup [in C:\Users\Prince\Desktop\microblog2\app\__init__.py:50]
2018-09-21 18:13:29,697 INFO: Microblog startup [in C:\Users\Prince\Desktop\microblog2\app\__init__.py:50]
2018-09-21 20:50:24,621 INFO: Microblog startup [in C:\Users\Prince\Desktop\microblog2\app\__init__.py:50]
2018-09-21 20:55:58,884 INFO: Microblog startup [in C:\Users\Prince\Desktop\microblog2\app\__init__.py:50]
2018-09-21 21:03:33,239 INFO: Microblog startup [in C:\Users\Prince\Desktop\microblog2\app\__init__.py:50]
2018-09-21 21:06:18,379 ERROR: Exception on /users/abcd [GET] [in C:\ProgramData\Anaconda3\lib\site-packages\flask\app.py:1560]
Traceback (most recent call last):
  File "C:\ProgramData\Anaconda3\lib\site-packages\flask\app.py", line 1982, in wsgi_app
    response = self.full_dispatch_request()
  File "C:\ProgramData\Anaconda3\lib\site-packages\flask\app.py", line 1614, in full_dispatch_request
    rv = self.handle_user_exception(e)
  File "C:\ProgramData\Anaconda3\lib\site-packages\flask\app.py", line 1517, in handle_user_exception
    reraise(exc_type, exc_value, tb)
  File "C:\ProgramData\Anaconda3\lib\site-packages\flask\_compat.py", line 33, in reraise
    raise value
  File "C:\ProgramData\Anaconda3\lib\site-packages\flask\app.py", line 1612, in full_dispatch_request
    rv = self.dispatch_request()
  File "C:\ProgramData\Anaconda3\lib\site-packages\flask\app.py", line 1598, in dispatch_request
    return self.view_functions[rule.endpoint](**req.view_args)
  File "C:\ProgramData\Anaconda3\lib\site-packages\flask_login\utils.py", line 261, in decorated_view
    return func(*args, **kwargs)
  File "C:\Users\Prince\Desktop\microblog2\app\routes6_1.py", line 68, in users
    return render_template('users.html',user=user,posts=posts)
  File "C:\ProgramData\Anaconda3\lib\site-packages\flask\templating.py", line 134, in render_template
    context, ctx.app)
  File "C:\ProgramData\Anaconda3\lib\site-packages\flask\templating.py", line 116, in _render
    rv = template.render(context)
  File "C:\ProgramData\Anaconda3\lib\site-packages\jinja2\asyncsupport.py", line 76, in render
    return original_render(self, *args, **kwargs)
  File "C:\ProgramData\Anaconda3\lib\site-packages\jinja2\environment.py", line 1008, in render
    return self.environment.handle_exception(exc_info, True)
  File "C:\ProgramData\Anaconda3\lib\site-packages\jinja2\environment.py", line 780, in handle_exception
    reraise(exc_type, exc_value, tb)
  File "C:\ProgramData\Anaconda3\lib\site-packages\jinja2\_compat.py", line 37, in reraise
    raise value.with_traceback(tb)
  File "C:\Users\Prince\Desktop\microblog2\app\templates\users.html", line 1, in top-level template code
    {% extends "base.html" %}
  File "C:\Users\Prince\Desktop\microblog2\app\templates\base.html", line 33, in top-level template code
    {% block content %}{% endblock %}
  File "C:\Users\Prince\Desktop\microblog2\app\templates\users.html", line 20, in block "content"
    <p><a href="{{ url_for('follow', username=user.username) }}">Follow</a></p>
  File "C:\ProgramData\Anaconda3\lib\site-packages\flask\helpers.py", line 333, in url_for
    return appctx.app.handle_url_build_error(error, endpoint, values)
  File "C:\ProgramData\Anaconda3\lib\site-packages\flask\app.py", line 1805, in handle_url_build_error
    reraise(exc_type, exc_value, tb)
  File "C:\ProgramData\Anaconda3\lib\site-packages\flask\_compat.py", line 33, in reraise
    raise value
  File "C:\ProgramData\Anaconda3\lib\site-packages\flask\helpers.py", line 323, in url_for
    force_external=external)
  File "C:\ProgramData\Anaconda3\lib\site-packages\werkzeug\routing.py", line 1768, in build
    raise BuildError(endpoint, values, method, self)
werkzeug.routing.BuildError: Could not build url for endpoint 'follow' with values ['username']. Did you mean 'login' instead?
2018-09-21 21:07:55,424 INFO: Microblog startup [in C:\Users\Prince\Desktop\microblog2\app\__init__.py:50]
2018-09-21 21:11:19,775 ERROR: Exception on /users/midoriya [GET] [in C:\ProgramData\Anaconda3\lib\site-packages\flask\app.py:1560]
Traceback (most recent call last):
  File "C:\ProgramData\Anaconda3\lib\site-packages\flask\app.py", line 1982, in wsgi_app
    response = self.full_dispatch_request()
  File "C:\ProgramData\Anaconda3\lib\site-packages\flask\app.py", line 1614, in full_dispatch_request
    rv = self.handle_user_exception(e)
  File "C:\ProgramData\Anaconda3\lib\site-packages\flask\app.py", line 1517, in handle_user_exception
    reraise(exc_type, exc_value, tb)
  File "C:\ProgramData\Anaconda3\lib\site-packages\flask\_compat.py", line 33, in reraise
    raise value
  File "C:\ProgramData\Anaconda3\lib\site-packages\flask\app.py", line 1612, in full_dispatch_request
    rv = self.dispatch_request()
  File "C:\ProgramData\Anaconda3\lib\site-packages\flask\app.py", line 1598, in dispatch_request
    return self.view_functions[rule.endpoint](**req.view_args)
  File "C:\ProgramData\Anaconda3\lib\site-packages\flask_login\utils.py", line 261, in decorated_view
    return func(*args, **kwargs)
  File "C:\Users\Prince\Desktop\microblog2\app\routes6_1.py", line 68, in users
    return render_template('users.html',user=user,posts=posts)
  File "C:\ProgramData\Anaconda3\lib\site-packages\flask\templating.py", line 134, in render_template
    context, ctx.app)
  File "C:\ProgramData\Anaconda3\lib\site-packages\flask\templating.py", line 116, in _render
    rv = template.render(context)
  File "C:\ProgramData\Anaconda3\lib\site-packages\jinja2\asyncsupport.py", line 76, in render
    return original_render(self, *args, **kwargs)
  File "C:\ProgramData\Anaconda3\lib\site-packages\jinja2\environment.py", line 1008, in render
    return self.environment.handle_exception(exc_info, True)
  File "C:\ProgramData\Anaconda3\lib\site-packages\jinja2\environment.py", line 780, in handle_exception
    reraise(exc_type, exc_value, tb)
  File "C:\ProgramData\Anaconda3\lib\site-packages\jinja2\_compat.py", line 37, in reraise
    raise value.with_traceback(tb)
  File "C:\Users\Prince\Desktop\microblog2\app\templates\users.html", line 1, in top-level template code
    {% extends "base.html" %}
  File "C:\Users\Prince\Desktop\microblog2\app\templates\base.html", line 33, in top-level template code
    {% block content %}{% endblock %}
  File "C:\Users\Prince\Desktop\microblog2\app\templates\users.html", line 20, in block "content"
    <p><a href="{{ url_for('follow', username=user.username) }}">Follow</a></p>
  File "C:\ProgramData\Anaconda3\lib\site-packages\flask\helpers.py", line 333, in url_for
    return appctx.app.handle_url_build_error(error, endpoint, values)
  File "C:\ProgramData\Anaconda3\lib\site-packages\flask\app.py", line 1805, in handle_url_build_error
    reraise(exc_type, exc_value, tb)
  File "C:\ProgramData\Anaconda3\lib\site-packages\flask\_compat.py", line 33, in reraise
    raise value
  File "C:\ProgramData\Anaconda3\lib\site-packages\flask\helpers.py", line 323, in url_for
    force_external=external)
  File "C:\ProgramData\Anaconda3\lib\site-packages\werkzeug\routing.py", line 1768, in build
    raise BuildError(endpoint, values, method, self)
werkzeug.routing.BuildError: Could not build url for endpoint 'follow' with values ['username']. Did you mean 'login' instead?
2018-09-22 16:51:35,706 INFO: Microblog startup [in C:\Users\Prince\Desktop\microblog2\app\__init__.py:50]
2018-09-22 16:53:16,321 INFO: Microblog startup [in C:\Users\Prince\Desktop\microblog2\app\__init__.py:50]
2018-09-22 16:55:35,953 INFO: Microblog startup [in C:\Users\Prince\Desktop\microblog2\app\__init__.py:50]
2018-09-22 16:56:42,944 INFO: Microblog startup [in C:\Users\Prince\Desktop\microblog2\app\__init__.py:50]
