2018-09-22 17:38:02,457 ERROR: Exception on /users/abcd [GET] [in C:\ProgramData\Anaconda3\lib\site-packages\flask\app.py:1560]
Traceback (most recent call last):
  File "C:\ProgramData\Anaconda3\lib\site-packages\flask\app.py", line 1982, in wsgi_app
    response = self.full_dispatch_request()
  File "C:\ProgramData\Anaconda3\lib\site-packages\flask\app.py", line 1614, in full_dispatch_request
    rv = self.handle_user_exception(e)
  File "C:\ProgramData\Anaconda3\lib\site-packages\flask\app.py", line 1517, in handle_user_exception
    reraise(exc_type, exc_value, tb)
  File "C:\ProgramData\Anaconda3\lib\site-packages\flask\_compat.py", line 33, in reraise
    raise value
  File "C:\ProgramData\Anaconda3\lib\site-packages\flask\app.py", line 1612, in full_dispatch_request
    rv = self.dispatch_request()
  File "C:\ProgramData\Anaconda3\lib\site-packages\flask\app.py", line 1598, in dispatch_request
    return self.view_functions[rule.endpoint](**req.view_args)
  File "C:\ProgramData\Anaconda3\lib\site-packages\flask_login\utils.py", line 261, in decorated_view
    return func(*args, **kwargs)
  File "C:\Users\Prince\Desktop\microblog2\app\routes6_1.py", line 68, in users
    return render_template('users.html',user=user,posts=posts)
  File "C:\ProgramData\Anaconda3\lib\site-packages\flask\templating.py", line 134, in render_template
    context, ctx.app)
  File "C:\ProgramData\Anaconda3\lib\site-packages\flask\templating.py", line 116, in _render
    rv = template.render(context)
  File "C:\ProgramData\Anaconda3\lib\site-packages\jinja2\asyncsupport.py", line 76, in render
    return original_render(self, *args, **kwargs)
  File "C:\ProgramData\Anaconda3\lib\site-packages\jinja2\environment.py", line 1008, in render
    return self.environment.handle_exception(exc_info, True)
  File "C:\ProgramData\Anaconda3\lib\site-packages\jinja2\environment.py", line 780, in handle_exception
    reraise(exc_type, exc_value, tb)
  File "C:\ProgramData\Anaconda3\lib\site-packages\jinja2\_compat.py", line 37, in reraise
    raise value.with_traceback(tb)
  File "C:\Users\Prince\Desktop\microblog2\app\templates\users.html", line 1, in top-level template code
    {% extends "base.html" %}
  File "C:\Users\Prince\Desktop\microblog2\app\templates\base.html", line 33, in top-level template code
    {% block content %}{% endblock %}
  File "C:\Users\Prince\Desktop\microblog2\app\templates\users.html", line 20, in block "content"
    <p><a href="{{ url_for('follow', username=user.username) }}">Follow</a></p>
  File "C:\ProgramData\Anaconda3\lib\site-packages\flask\helpers.py", line 333, in url_for
    return appctx.app.handle_url_build_error(error, endpoint, values)
  File "C:\ProgramData\Anaconda3\lib\site-packages\flask\app.py", line 1805, in handle_url_build_error
    reraise(exc_type, exc_value, tb)
  File "C:\ProgramData\Anaconda3\lib\site-packages\flask\_compat.py", line 33, in reraise
    raise value
  File "C:\ProgramData\Anaconda3\lib\site-packages\flask\helpers.py", line 323, in url_for
    force_external=external)
  File "C:\ProgramData\Anaconda3\lib\site-packages\werkzeug\routing.py", line 1768, in build
    raise BuildError(endpoint, values, method, self)
werkzeug.routing.BuildError: Could not build url for endpoint 'follow' with values ['username']. Did you mean 'login' instead?
2018-09-22 17:44:28,270 INFO: Microblog startup [in C:\Users\Prince\Desktop\microblog2\app\__init__.py:50]
2018-09-22 17:44:34,059 INFO: Microblog startup [in C:\Users\Prince\Desktop\microblog2\app\__init__.py:50]
2018-09-22 18:10:33,171 INFO: Microblog startup [in C:\Users\Prince\Desktop\microblog2\app\__init__.py:50]
2018-09-22 18:15:12,995 ERROR: Exception on /users/prince [GET] [in C:\ProgramData\Anaconda3\lib\site-packages\flask\app.py:1560]
Traceback (most recent call last):
  File "C:\ProgramData\Anaconda3\lib\site-packages\flask\app.py", line 1982, in wsgi_app
    response = self.full_dispatch_request()
  File "C:\ProgramData\Anaconda3\lib\site-packages\flask\app.py", line 1614, in full_dispatch_request
    rv = self.handle_user_exception(e)
  File "C:\ProgramData\Anaconda3\lib\site-packages\flask\app.py", line 1517, in handle_user_exception
    reraise(exc_type, exc_value, tb)
  File "C:\ProgramData\Anaconda3\lib\site-packages\flask\_compat.py", line 33, in reraise
    raise value
  File "C:\ProgramData\Anaconda3\lib\site-packages\flask\app.py", line 1612, in full_dispatch_request
    rv = self.dispatch_request()
  File "C:\ProgramData\Anaconda3\lib\site-packages\flask\app.py", line 1598, in dispatch_request
    return self.view_functions[rule.endpoint](**req.view_args)
  File "C:\ProgramData\Anaconda3\lib\site-packages\flask_login\utils.py", line 261, in decorated_view
    return func(*args, **kwargs)
  File "C:\Users\Prince\Desktop\microblog2\app\routes6_1.py", line 68, in users
    return render_template('users.html',user=user,posts=posts)
  File "C:\ProgramData\Anaconda3\lib\site-packages\flask\templating.py", line 134, in render_template
    context, ctx.app)
  File "C:\ProgramData\Anaconda3\lib\site-packages\flask\templating.py", line 116, in _render
    rv = template.render(context)
  File "C:\ProgramData\Anaconda3\lib\site-packages\jinja2\asyncsupport.py", line 76, in render
    return original_render(self, *args, **kwargs)
  File "C:\ProgramData\Anaconda3\lib\site-packages\jinja2\environment.py", line 1008, in render
    return self.environment.handle_exception(exc_info, True)
  File "C:\ProgramData\Anaconda3\lib\site-packages\jinja2\environment.py", line 780, in handle_exception
    reraise(exc_type, exc_value, tb)
  File "C:\ProgramData\Anaconda3\lib\site-packages\jinja2\_compat.py", line 37, in reraise
    raise value.with_traceback(tb)
  File "C:\Users\Prince\Desktop\microblog2\app\templates\users.html", line 1, in top-level template code
    {% extends "base.html" %}
  File "C:\Users\Prince\Desktop\microblog2\app\templates\base.html", line 33, in top-level template code
    {% block content %}{% endblock %}
  File "C:\Users\Prince\Desktop\microblog2\app\templates\users.html", line 20, in block "content"
    <p><a href="{{ url_for('follow', username=user.username) }}">Follow</a></p>
  File "C:\ProgramData\Anaconda3\lib\site-packages\flask\helpers.py", line 333, in url_for
    return appctx.app.handle_url_build_error(error, endpoint, values)
  File "C:\ProgramData\Anaconda3\lib\site-packages\flask\app.py", line 1805, in handle_url_build_error
    reraise(exc_type, exc_value, tb)
  File "C:\ProgramData\Anaconda3\lib\site-packages\flask\_compat.py", line 33, in reraise
    raise value
  File "C:\ProgramData\Anaconda3\lib\site-packages\flask\helpers.py", line 323, in url_for
    force_external=external)
  File "C:\ProgramData\Anaconda3\lib\site-packages\werkzeug\routing.py", line 1768, in build
    raise BuildError(endpoint, values, method, self)
werkzeug.routing.BuildError: Could not build url for endpoint 'follow' with values ['username']. Did you mean 'login' instead?
2018-09-22 18:18:23,465 INFO: Microblog startup [in C:\Users\Prince\Desktop\microblog2\app\__init__.py:50]
2018-09-22 18:21:10,006 INFO: Microblog startup [in C:\Users\Prince\Desktop\microblog2\app\__init__.py:50]
2018-09-22 18:26:31,549 INFO: Microblog startup [in C:\Users\Prince\Desktop\microblog2\app\__init__.py:50]
2018-09-22 18:38:43,981 INFO: Microblog startup [in C:\Users\Prince\Desktop\microblog2\app\__init__.py:50]
2018-09-22 20:12:50,127 INFO: Microblog startup [in C:\Users\Prince\Desktop\microblog2\app\__init__.py:50]
2018-09-22 20:13:43,689 ERROR: Exception on /follow/aditya_mathur [GET] [in C:\ProgramData\Anaconda3\lib\site-packages\flask\app.py:1560]
Traceback (most recent call last):
  File "C:\ProgramData\Anaconda3\lib\site-packages\flask\app.py", line 1982, in wsgi_app
    response = self.full_dispatch_request()
  File "C:\ProgramData\Anaconda3\lib\site-packages\flask\app.py", line 1614, in full_dispatch_request
    rv = self.handle_user_exception(e)
  File "C:\ProgramData\Anaconda3\lib\site-packages\flask\app.py", line 1517, in handle_user_exception
    reraise(exc_type, exc_value, tb)
  File "C:\ProgramData\Anaconda3\lib\site-packages\flask\_compat.py", line 33, in reraise
    raise value
  File "C:\ProgramData\Anaconda3\lib\site-packages\flask\app.py", line 1612, in full_dispatch_request
    rv = self.dispatch_request()
  File "C:\ProgramData\Anaconda3\lib\site-packages\flask\app.py", line 1598, in dispatch_request
    return self.view_functions[rule.endpoint](**req.view_args)
  File "C:\ProgramData\Anaconda3\lib\site-packages\flask_login\utils.py", line 261, in decorated_view
    return func(*args, **kwargs)
  File "C:\Users\Prince\Desktop\microblog2\app\routes6_1.py", line 24, in follow
    return redirect(url_for('user',username=username))
  File "C:\ProgramData\Anaconda3\lib\site-packages\flask\helpers.py", line 333, in url_for
    return appctx.app.handle_url_build_error(error, endpoint, values)
  File "C:\ProgramData\Anaconda3\lib\site-packages\flask\app.py", line 1805, in handle_url_build_error
    reraise(exc_type, exc_value, tb)
  File "C:\ProgramData\Anaconda3\lib\site-packages\flask\_compat.py", line 33, in reraise
    raise value
  File "C:\ProgramData\Anaconda3\lib\site-packages\flask\helpers.py", line 323, in url_for
    force_external=external)
  File "C:\ProgramData\Anaconda3\lib\site-packages\werkzeug\routing.py", line 1768, in build
    raise BuildError(endpoint, values, method, self)
werkzeug.routing.BuildError: Could not build url for endpoint 'user' with values ['username']. Did you mean 'users' instead?
2018-09-22 20:25:12,736 INFO: Microblog startup [in C:\Users\Prince\Desktop\microblog2\app\__init__.py:50]
2018-09-22 20:29:55,587 INFO: Microblog startup [in C:\Users\Prince\Desktop\microblog2\app\__init__.py:50]
2018-09-22 23:58:24,793 INFO: Microblog startup [in C:\Users\Prince\Desktop\microblog2\app\__init__.py:50]
2018-09-23 03:10:56,945 INFO: Microblog startup [in C:\Users\Prince\Desktop\microblog2\app\__init__.py:50]
